Workbook

Sheet Sammlung Start
A1: Sammlung – Gesamtübersicht
A2: Postkarten und Münzen getrennt bewertet, gemeinsam im Blick
A4: Artikel gesamt | C4: Aktueller Gesamt-VK | E4: Marktwert gesamt | G4: Differenz zum Markt | I4: Preisabweichungen | L4: Münzen prüfen
A5: =COUNTA(Postkarten!A2:'Postkarten'!A616)+COUNTA(Münzen!A5:A13) -> 623 | C5: =SUM(Postkarten!N2:'Postkarten'!N622)+SUM(Münzen!N5:N13) -> 5335.9 | E5: =SUM(Preisvergleich[Ermittelt VK])+SUM(MuenzenPreisvergleich[Ermittelt VK]) -> 3576.4 | G5: =E5-C5 -> -1759.5 | I5: =COUNTIF(Preisvergleich[Differenz VK],"<>0")+COUNTIF(MuenzenPreisvergleich[Differenz VK],"<>0") -> 68 | L5: =COUNTIF(MuenzenPreisvergleich[Bewertung],"Identifikation prüfen") -> 5
A9: Sammlungsbereich | B9: Artikel | C9: Aktueller VK | D9: Marktwert | E9: Differenz | G9: Bereich | H9: Erhöhen | I9: Senken | J9: Unverändert | K9: Identifikation prüfen
A10: Postkarten | B10: =COUNTA(Postkarten!A2:A410) -> 408 | C10: =SUM(Postkarten!N2:N410) -> 3303.4 | D10: =SUM(Preisvergleich[Ermittelt VK]) -> 3224.4 | E10: =D10-C10 -> -79 | G10: Postkarten | H10: =COUNTIF(Preisvergleich[Bewertung],"Erhöhen") -> 12 | I10: =COUNTIF(Preisvergleich[Bewertung],"Senken") -> 52 | J10: =COUNTIF(Preisvergleich[Bewertung],"Unverändert") -> 344 | K10: 0
A11: Münzen | B11: =COUNTA(Münzen!A5:A13) -> 9 | C11: =SUM(Münzen!N5:N13) -> 340 | D11: =SUM(MuenzenPreisvergleich[Ermittelt VK]) -> 352 | E11: =D11-C11 -> 12 | G11: Münzen | H11: =COUNTIF(MuenzenPreisvergleich[Bewertung],"Erhöhen") -> 2 | I11: =COUNTIF(MuenzenPreisvergleich[Bewertung],"Senken") -> 1 | J11: =COUNTIF(MuenzenPreisvergleich[Bewertung],"Unverändert") -> 1 | K11: =COUNTIF(MuenzenPreisvergleich[Bewertung],"Identifikation prüfen") -> 5
A14: Empfohlene Reihenfolge
A15: 1 | B15: Postkarten Dashboard | C15: Verkaufssteuerung, Orte, Preisbereiche und Top-Angebote
A16: 2 | B16: Postkarten Vergleich | C16: Marktwerte und Preisabweichungen aller Postkarten
A17: 3 | B17: Münzen | C17: Bestand, Erhaltungsgrade und eigene Preisansätze
A18: 4 | B18: Münzen Vergleich | C18: Marktwerte und Identifikationshinweise der Münzen
A21: Hinweis zum Münzfoto: Die neun Münzen sind sichtbar, aber Jahrgänge, Nominale und Münzzeichen sind nicht bei allen Stücken sicher lesbar. Die mit „Identifikation prüfen“ markierten Bewertungen bleiben vorläufig, bis Vorder- und Rückseite jeder Münze einzeln fotografiert wurden.

Sheet Postkarten Dashboard
A1: Webshop-Start: Verkaufsübersicht
A2: Bestand, Preispositionierung und Datenqualität für einen strukturierten Verkaufsstart
A4: Karten | C4: Aktueller VK | E4: Ø VK / Karte | G4: Marktvergleich | I4: Preis anpassen | K4: Artikel-Duplikate
A5: =COUNTA(Postkarten!$A$2:$A$695) -> 635 | C5: =SUM(Postkarten!$N$2:$N$695) -> 5101.9 | E5: =IFERROR(C5/A5,0) -> 8.0344882 | G5: =IFERROR(COUNTIF(Preisvergleich[Artikelnummer],"AK-*")/A5,0) -> 0.64251969 | I5: =COUNTIFS(Preisvergleich[Artikelnummer],"AK-*",Preisvergleich[Differenz VK],"<>0") -> 64 | K5: {=COUNTA(_xlfn._xlws.FILTER(Postkarten!$A$2:$A$410,Postkarten!$A$2:$A$410<>""))-ROWS(_xlfn.UNIQUE(_xlfn._xlws.FILTER(Postkarten!$A$2:$A$410,Postkarten!$A$2:$A$410<>"")))} -> 0
A8: Top-Orte | B8: Karten | C8: VK-Summe | E8: Preissegment | F8: Karten | G8: VK-Summe | I8: Datenqualität | J8: Offen | K8: Priorität
A9: München | B9: =COUNTIF(Postkarten!$D$2:$D$410,A9&"*") -> 54 | C9: =SUMIF(Postkarten!$D$2:$D$410,A9&"*",Postkarten!$N$2:$N$410) -> 492 | E9: Premium (≥ 12 €) | F9: =COUNTIF(Postkarten!$N$2:$N$410,">=12") -> 46 | G9: =SUMIF(Postkarten!$N$2:$N$410,">=12",Postkarten!$N$2:$N$410) -> 670.4 | I9: Ohne Marktvergleich | J9: =A5-ROWS(Preisvergleich[Artikelnummer]) -> 227 | K9: Hoch
A10: Regensburg | B10: =COUNTIF(Postkarten!$D$2:$D$410,A10&"*") -> 42 | C10: =SUMIF(Postkarten!$D$2:$D$410,A10&"*",Postkarten!$N$2:$N$410) -> 333.5 | E10: Kernsortiment (8–11,99 €) | F10: =COUNTIFS(Postkarten!$N$2:$N$410,">=8",Postkarten!$N$2:$N$410,"<12") -> 152 | G10: =SUMIFS(Postkarten!$N$2:$N$410,Postkarten!$N$2:$N$410,">=8",Postkarten!$N$2:$N$410,"<12") -> 1362 | I10: Doppelte Artikelnummern | J10: =K5 -> 0 | K10: Hoch
A11: Nürnberg | B11: =COUNTIF(Postkarten!$D$2:$D$410,A11&"*") -> 24 | C11: =SUMIF(Postkarten!$D$2:$D$410,A11&"*",Postkarten!$N$2:$N$410) -> 198.5 | E11: Standard (5–7,99 €) | F11: =COUNTIFS(Postkarten!$N$2:$N$410,">=5",Postkarten!$N$2:$N$410,"<8") -> 201 | G11: =SUMIFS(Postkarten!$N$2:$N$410,Postkarten!$N$2:$N$410,">=5",Postkarten!$N$2:$N$410,"<8") -> 1234 | I11: Verlag unbekannt | J11: =COUNTIF(Postkarten!$C$2:$C$410,"*Unbekannt*") -> 73 | K11: Mittel
A12: Parsberg | B12: =COUNTIF(Postkarten!$D$2:$D$410,A12&"*") -> 22 | C12: =SUMIF(Postkarten!$D$2:$D$410,A12&"*",Postkarten!$N$2:$N$410) -> 218.4 | E12: Bündel (< 5 €) | F12: =COUNTIF(Postkarten!$N$2:$N$410,"<5") -> 10 | G12: =SUMIF(Postkarten!$N$2:$N$410,"<5",Postkarten!$N$2:$N$410) -> 37 | I12: Jahr unklar | J12: =COUNTIF(Postkarten!$I$2:$I$410,"*Unbekannt*")+COUNTIF(Postkarten!$I$2:$I$410,"Keiner") -> 74 | K12: Mittel
A13: Lupburg | B13: =COUNTIF(Postkarten!$D$2:$D$410,A13&"*") -> 13 | C13: =SUMIF(Postkarten!$D$2:$D$410,A13&"*",Postkarten!$N$2:$N$410) -> 139 | I13: Stempel unklar | J13: =COUNTIF(Postkarten!$J$2:$J$410,"*Unbekannt*")+COUNTIF(Postkarten!$J$2:$J$410,"Keiner") -> 93 | K13: Niedrig
A14: Donaustauf | B14: =COUNTIF(Postkarten!$D$2:$D$410,A14&"*") -> 8 | C14: =SUMIF(Postkarten!$D$2:$D$410,A14&"*",Postkarten!$N$2:$N$410) -> 75 | I14: Empfänger/Absender unklar | J14: =COUNTIF(Postkarten!$K$2:$K$410,"*Unbekannt*")+COUNTIF(Postkarten!$K$2:$K$410,"Keine") -> 112 | K14: Niedrig
A15: Herrenchiemsee | B15: =COUNTIF(Postkarten!$D$2:$D$410,A15&"*") -> 7 | C15: =SUMIF(Postkarten!$D$2:$D$410,A15&"*",Postkarten!$N$2:$N$410) -> 46
A16: Oberammergau | B16: =COUNTIF(Postkarten!$D$2:$D$410,A16&"*") -> 7 | C16: =SUMIF(Postkarten!$D$2:$D$410,A16&"*",Postkarten!$N$2:$N$410) -> 64
A17: Rothenburg ob der Tauber | B17: =COUNTIF(Postkarten!$D$2:$D$410,A17&"*") -> 7 | C17: =SUMIF(Postkarten!$D$2:$D$410,A17&"*",Postkarten!$N$2:$N$410) -> 48
A18: Passau | B18: =COUNTIF(Postkarten!$D$2:$D$410,A18&"*") -> 5 | C18: =SUMIF(Postkarten!$D$2:$D$410,A18&"*",Postkarten!$N$2:$N$410) -> 37
A21: Verkaufspriorität – höchste aktuelle Einzelwerte | J21: Start-Checkliste
A22: Rang | B22: Artikelnummer | C22: Titel | D22: Ort | E22: VK | F22: Markt-VK | G22: Differenz | H22: Empfehlung | J22: Nr. | K22: Aufgabe | L22: Umfang | M22: Status | N22: Nutzen
A23: {=_xlfn.LET(_xlpm.ids,_xlfn._xlws.FILTER(Postkarten!$A$2:$A$410,Postkarten!$A$2:$A$410<>""),_xlpm.ttl,_xlfn._xlws.FILTER(Postkarten!$B$2:$B$410,Postkarten!$A$2:$A$410<>""),_xlpm.ort,_xlfn._xlws.FILTER(Postkarten!$D$2:$D$410,Postkarten!$A$2:$A$410<>""),_xlpm.vk,_xlfn._xlws.FILTER(Postkarten!$N$2:$N$410,Postkarten!$A$2:$A$410<>""),_xlpm.d,_xlfn.HSTACK(_xlpm.ids,_xlpm.ttl,_xlpm.ort,_xlpm.vk),_xlpm.z,_xlfn.TAKE(_xlfn.SORTBY(_xlpm.d,_xlpm.vk,-1),12),_xlpm.mv,_xlfn.XLOOKUP(_xlfn.CHOOSECOLS(_xlpm.z,1),Preisvergleich[Artikelnummer],Preisvergleich[Ermittelt VK],0),_xlpm.df,_xlpm.mv-_xlfn.CHOOSECOLS(_xlpm.z,4),_xlfn.HSTACK(_xlfn.SEQUENCE(12),_xlpm.z,_xlpm.mv,_xlpm.df,IF(_xlpm.df>0,"Erhöhen",IF(_xlpm.df<0,"Senken","Unverändert"))))} -> 1 | B23: AK-2026-0331 | C23: Gilching, Villenkolonie | D23: Gilching / Oberbayern / Bayern | E23: 28 | F23: 28 | G23: 0 | H23: Unverändert | J23: 1 | K23: Fehlende Marktvergleiche ergänzen | L23: =A5-ROWS(Preisvergleich[Artikelnummer]) -> 227 | M23: =IF(L23=0,"Bereit","Offen") -> Offen | N23: Preisrisiko reduzieren
A24: 2 | B24: AK-2026-0026 | C24: Dürnsricht – Blick auf Dürnsricht mit Bäckerei & Kolonialwarengeschäft Bartmann | D24: Dürnsricht | E24: 25 | F24: 25 | G24: 0 | H24: Unverändert | J24: 2 | K24: Doppelte Artikelnummern bereinigen | L24: =K5 -> 0 | M24: =IF(L24=0,"Bereit","Offen") -> Bereit | N24: Bestellungen eindeutig zuordnen
A25: 3 | B25: AK-2026-0268 | C25: München - Klapp-Werbebriefkarte Drei Masken Verlag | D25: München / Oberbayern | E25: 22 | F25: 22 | G25: 0 | H25: Unverändert | J25: 3 | K25: Premium-Karten einzeln fotografieren | L25: =F9 -> 46 | M25: Offen | N25: Höherer Erlös je Listing
A26: 4 | B26: AK-2026-0370 | C26: Schloss Herrenchiemsee – Salle de l'oeil de boeuf (Ochsenaugensaal) | D26: Chiemsee / Herrenchiemsee / Oberbayern / Bayern | E26: 22 | F26: 22 | G26: 0 | H26: Unverändert | J26: 4 | K26: Standardkarten zu Themen-Bundles bündeln | L26: =F12 -> 10 | M26: Offen | N26: Aufwand und Versand senken
A27: 5 | B27: AK-2026-0344 | C27: Walhalla a. Donau bei Regensburg (Erbaut 1830–1842 durch König Ludwig I., Entwurf von Leo von Klenze) | D27: Donaustauf / Regensburg / Oberpfalz / Bayern | E27: 20 | F27: 20 | G27: 0 | H27: Unverändert | J27: 5 | K27: Verlagsangaben nachpflegen | L27: =J11 -> 73 | M27: Offen | N27: Suche und SEO verbessern
A28: 6 | B28: AK-2026-0345 | C28: Gaststätte „Tiroler Höhe“ Nürnberg-S. am Hasenbuck | D28: Nürnberg / Mittelfranken / Bayern[cite: 14] | E28: 20 | F28: 6 | G28: -14 | H28: Senken | J28: 6 | K28: Datierung nachpflegen | L28: =J12 -> 74 | M28: Offen | N28: Sammlerrelevanz erhöhen
A29: 7 | B29: AK-2026-0133 | C29: XXIII. Bundestag des D. R. B. Nürnberg (Kaiserburg) | D29: Nürnberg | E29: 19 | F29: 19 | G29: 0 | H29: Unverändert | J29: 7 | K29: Listing-Mindeststandard erfüllt | L29: =A5 -> 635 | M29: Bereit | N29: Titel, Zustand, Preis, Status vorhanden
A30: 8 | B30: AK-2026-0084 | C30: Prinz Regent Luitpold von Bayern – Jubiläums-Postkarte 1821–1911 | D30: München / Bayern | E30: 18 | F30: 12 | G30: -6 | H30: Senken
A31: 9 | B31: AK-2026-0085 | C31: Prinz Regent Luitpold von Bayern – Jubiläums-Postkarte mit Mädchen (1911) | D31: München / Bayern | E31: 18 | F31: 12 | G31: -6 | H31: Senken
A32: 10 | B32: AK-2026-0158 | C32: Granit-Steinbruch Zeinried! | D32: Zeinried / Oberpfalz | E32: 18 | F32: 18 | G32: 0 | H32: Unverändert
A33: 11 | B33: AK-2026-0017 | C33: Regensburg – Moltkeplatz im Schnee (Nachtschneekarte mit Dom) | D33: Regensburg | E33: 15 | F33: 15 | G33: 0 | H33: Unverändert
A34: 12 | B34: AK-2026-0111 | C34: Blick auf München vom Maximilianeum aus | D34: München | E34: 15 | F34: 15 | G34: 0 | H34: Unverändert
A37: Größte Preis-Chancen laut Vergleich | J37: Preis-Senkungen mit höchster Dringlichkeit
A38: Artikelnummer | B38: Titel | C38: Aktuell VK | D38: Markt-VK | E38: Potenzial | F38: Ort | G38: Quellzeile | H38: Aktion | J38: Artikelnummer | K38: Titel | L38: Aktuell | M38: Markt | N38: Differenz
A39: {=IFERROR(_xlfn.LET(_xlpm.d,_xlfn._xlws.FILTER(_xlfn.HSTACK(Preisvergleich[Artikelnummer],Preisvergleich[Titel],Preisvergleich[Aktuell VK],Preisvergleich[Ermittelt VK],Preisvergleich[Differenz VK],_xlfn.XLOOKUP(Preisvergleich[Artikelnummer],Postkarten!A2:A410,Postkarten!D2:D410,""),Preisvergleich[Quellzeile]),(Preisvergleich[Differenz VK]>0)*(LEFT(Preisvergleich[Artikelnummer],3)="AK-")),_xlpm.z,_xlfn.TAKE(_xlfn.SORTBY(_xlpm.d,_xlfn.CHOOSECOLS(_xlpm.d,5),-1),10),_xlfn.HSTACK(_xlpm.z,IF(_xlfn.CHOOSECOLS(_xlpm.z,5)>0,"Preis prüfen/erhöhen",""))),"Keine Erhöhungen offen")} -> AK-2026-0396 | B39: Gruß aus Ensdorf bei Amberg Opf. | C39: 7 | D39: 14 | E39: 7 | F39: Ensdorf / Oberpfalz / Bayern | G39: 398 | H39: Preis prüfen/erhöhen | J39: {=_xlfn.LET(_xlpm.d,_xlfn._xlws.FILTER(_xlfn.HSTACK(Preisvergleich[Artikelnummer],Preisvergleich[Titel],Preisvergleich[Aktuell VK],Preisvergleich[Ermittelt VK],Preisvergleich[Differenz VK]),(Preisvergleich[Differenz VK]<0)*(LEFT(Preisvergleich[Artikelnummer],3)="AK-")),_xlfn.TAKE(_xlfn.SORTBY(_xlpm.d,_xlfn.CHOOSECOLS(_xlpm.d,5),1),10))} -> AK-2026-0345 | K39: Gaststätte „Tiroler Höhe“ Nürnberg-S. am Hasenbuck | L39: 20 | M39: 6 | N39: -14
A40: AK-2026-0397 | B40: Ansbach – Krankenhaus | C40: 6 | D40: 13 | E40: 7 | F40: Ansbach / Mittelfranken / Bayern | G40: 399 | H40: Preis prüfen/erhöhen | J40: AK-2026-0084 | K40: Prinz Regent Luitpold von Bayern – Jubiläums-Postkarte 1821–1911 | L40: 18 | M40: 12 | N40: -6
A41: AK-2026-0384 | B41: Roth a/ See | C41: 6 | D41: 9 | E41: 3 | F41: Roth an der Saale / Unterfranken / Bayern | G41: 386 | H41: Preis prüfen/erhöhen | J41: AK-2026-0085 | K41: Prinz Regent Luitpold von Bayern – Jubiläums-Postkarte mit Mädchen (1911) | L41: 18 | M41: 12 | N41: -6
A42: AK-2026-0400 | B42: Schloß Parsberg / Bayrische Oberpfalz | C42: 7 | D42: 10 | E42: 3 | F42: Parsberg / Oberpfalz / Bayern | G42: 402 | H42: Preis prüfen/erhöhen | J42: AK-2026-0343 | K42: München - Ehrentempel am Königlichen Platz | L42: 10 | M42: 6 | N42: -4
A43: AK-2026-0382 | B43: Zenting, bayr. Wald | C43: 4 | D43: 6 | E43: 2 | F43: Zenting / Niederbayern / Bayern | G43: 384 | H43: Preis prüfen/erhöhen | J43: AK-2026-0156 | K43: Gruss vom Oberammergauer Passionsspiel (Bühnenansicht) | L43: 12 | M43: 9 | N43: -3
A44: AK-2026-0383 | B44: Zenting, bayr. Wald | C44: 4 | D44: 6 | E44: 2 | F44: Zenting / Niederbayern / Bayern | G44: 385 | H44: Preis prüfen/erhöhen | J44: AK-2026-0310 | K44: Gruß aus Seubersdorf (Mehrfach-Luftbildkarte) | L44: 12 | M44: 9 | N44: -3
A45: AK-2026-0236 | B45: Schwarzenkopfhütte über Neuhaus b. Schliersee | C45: 6 | D45: 8 | E45: 2 | F45: Schliersee / Oberbayern / Bayern | G45: 237 | H45: Preis prüfen/erhöhen | J45: AK-2026-0311 | K45: Feldkirchen b. Westerham gegen Wendelstein (1884 m) | L45: 9 | M45: 6 | N45: -3
A46: AK-2026-0381 | B46: Feste Koburg aus einem Flugzeug gesehen | C46: 5 | D46: 6 | E46: 1 | F46: Coburg / Oberfranken / Bayern | G46: 383 | H46: Preis prüfen/erhöhen | J46: AK-2026-0312 | K46: Luftbild Sulzbürg / Opf. | L46: 11 | M46: 8 | N46: -3
A47: AK-2026-0390 | B47: Regensburg – Blick auf die Stadt von den Winserer Höhen | C47: 6 | D47: 7 | E47: 1 | F47: Regensburg / Oberpfalz / Bayern | G47: 392 | H47: Preis prüfen/erhöhen | J47: AK-2026-0314 | K47: Seubersdorf Opf. (Mehrfach-Luftbildkarte mit Bäckerei Anton Liedl) | L47: 15 | M47: 12 | N47: -3
...

Sheet Postkarten
A1: Artikelnummer | B1: Titel | C1: Verlag | D1: Ort / Region | E1: Kategorie / Motiv | F1: Erhaltungszustand | G1: Zustand Details | H1: Gelaufen (J/N) | I1: Baujahr / Postamt | J1: Stempel Info | K1: Empfänger / Absender | L1: Wert Min (€) | M1: Wert Max (€) | N1: Verkaufspreis (€) | O1: Status | P1: Besondere Merkmale | Q1: Bekannte Mängel
A2: AK-2026-0001 | B2: München – Karlsplatz (Stachus) mit Steinbogen und Stadtwappen | C2: Historischer Kunstverlag | D2: München | E2: Topografie / Stadtansicht | F2: Gut (Z2) | G2: Schöne Lithografie mit Zierrahmen, gelaufen | H2: Ja | I2: ca. 1905 | J2: München Postamt | K2: Sammlungsbestand | L2: 4 | M2: 8 | N2: =MAX(L2,M2) -> 8 | O2: Im Bestand | P2: Lithografie, Wappen
A3: AK-2026-0002 | B3: Straubing – Ludwigsplatz (Blick vom unteren Tor) | C3: Lokaler Verlag Straubing | D3: Straubing | E3: Topografie / Straßenbild | F3: Gut (Z2) | G3: Vorderseitig beschrieben, sauberer Erhalt | H3: Ja | I3: ca. 1908 | J3: Straubing | K3: Sammlungsbestand | L3: 3 | M3: 6 | N3: =MAX(L3,M3) -> 6 | O3: Im Bestand | P3: Historischer Straßenzug
A4: AK-2026-0003 | B4: Nürnberg – Schöner Brunnen mit Marktgeschehen | C4: Ottmar Zieher | D4: Nürnberg | E4: Topografie / Sehenswürdigkeit | F4: Altersentsprechend (Z2-3) | G4: Vorderseite stark beschrieben, optischer Zustand etwas eingeschränkt | H4: Ja | I4: ca. 1906 | J4: Nürnberg | K4: Sammlungsbestand | L4: 2.5 | M4: 5 | N4: =MAX(L4,M4) -> 5 | O4: Im Bestand | P4: Marktgeschehen, beschriebene Vorderseite
A5: AK-2026-0004 | B5: Beratzhausen – Gesamtansicht (gelaufen über Holnstein nach Lupburg) | C5: Lokaler Verlag | D5: Beratzhausen / Holnstein | E5: Topografie / Oberpfalz | F5: Sehr gut (Z1-2) | G5: Sauber gestempelt, schöne Handschrift | H5: Ja | I5: 1909 | J5: Holnstein / Lupburg | K5: An Josef Pauerer | L5: 4 | M5: 7 | N5: =MAX(L5,M5) -> 7 | O5: Im Bestand | P5: Heimatkarte Oberpfalz, Stempel Holnstein
A6: AK-2026-0005 | B6: München – Künstler-Jubiläumskarte 1821–1911 (W. Diez, Oscar Consée) | C6: Oscar Consée, München 5 | D6: München | E6: Künstlerkarte / Jubiläum | F6: Sehr gut (Z1) | G6: Ungelaufen, brillante Farben | H6: Nein | I6: 1910 / 1911 | J6: Ungestempelt | K6: Unbeschrieben | L6: 6 | M6: 12 | N6: =MAX(L6,M6) -> 12 | O6: Im Bestand | P6: Signiert W. Diez, Prinzregent Luitpold Jubiläum
A7: AK-2026-0006 | B7: München – Künstler-Jubiläumskarte 1821–1911 (gelaufen nach Beratzhausen 1911) | C7: Oscar Consée, München 5 | D7: München / Beratzhausen | E7: Künstlerkarte / Jubiläum | F7: Gut (Z2) | G7: Gelaufen mit Marke und Stempel Lupburg 1911 | H7: Ja | I7: 1911 | J7: Lupburg, 10.03.1911 | K7: Josef Pauerer / Josef Vogl Geschwister | L7: 8 | M7: 14 | N7: =MAX(L7,M7) -> 14 | O7: Im Bestand | P7: Sütterlin-Text, Prinzregent Luitpold
A8: AK-2026-0007 | B8: München – Künstler-Jubiläumskarte 1911 mit Kindern (gelaufen nach Beratzhausen) | C8: Oscar Consée, München 5 | D8: München / Beratzhausen | E8: Künstlerkarte / Jubiläum | F8: Befriedigend bis Gut (Z2-3) | G8: Starke Flecken/Verschmutzungen am Unterrand | H8: Ja | I8: 1911 | J8: Lupburg, 10.03.1911 | K8: Josef Pauerer / Vater, Mutti & Geschwister | L8: 3 | M8: 6 | N8: =MAX(L8,M8) -> 6 | O8: Im Bestand | P8: Kindermotiv, Randverschmutzungen
A9: AK-2026-0008 | B9: München – Künstler-Jubiläumskarte 1911 mit Kindern (ungelaufen, Randspuren) | C9: Oscar Consée, München 5 | D9: München | E9: Künstlerkarte / Jubiläum | F9: Befriedigend bis Gut (Z2-3) | G9: Vorderseitig leichte Klebe- und Schmutzspuren unten, ungelaufen | H9: Nein | I9: ca. 1911 | J9: Ungestempelt | K9: Unbeschrieben | L9: 3 | M9: 6 | N9: =MAX(L9,M9) -> 6 | O9: Im Bestand | P9: Kindermotiv, ungelaufene Variante
A10: AK-2026-0009 | B10: München – Künstler-Jubiläumskarte 1911 mit Kindern (sauberer Zustand, ungelaufen) | C10: Oscar Consée, München 5 | D10: München | E10: Künstlerkarte / Jubiläum | F10: Sehr gut (Z1-2) | G10: Vorderseite sauber, Kanten gut erhalten, ungelaufen | H10: Nein | I10: ca. 1911 | J10: Ungestempelt | K10: Unbeschrieben | L10: 5 | M10: 9 | N10: =MAX(L10,M10) -> 9 | O10: Im Bestand | P10: Kindermotiv, sehr guter Zustand
A11: AK-2026-0010 | B11: Nürnberg – Prinzregenten-Denkmal mit Edelweiß-Prägung | C11: Paul Seyfert, Dresden (No. 904) | D11: Nürnberg | E11: Denkmäler / Prägekarte | F11: Sehr gut (Z1-2) | G11: Vorderseite kräftige Prägung, leichte Eckenbestoßung unten; gelaufen mit 5-Pfennig Bayern-Marke | H11: Ja | I11: 1901 | J11: Nürnberg / Schleiz, 03.05.1901 | K11: Otto Rahtel, b. Schleiz (Reuß) | L11: 6 | M11: 12 | N11: =MAX(L11,M11) -> 12 | O11: Im Bestand | P11: Prägung / Relief, Edelweiß, Sütterlin / Handschrift
A12: AK-2026-0011 | B12: Regensburg – Emmeranerthor mit Seitenflügel des Fürstlichen Taxis Palais | C12: Jacob Frankel, Regensburg (No. 565) | D12: Regensburg | E12: Topografie / Lithografie | F12: Sehr gut (Z1-2) | G12: Vorderseitig mit Wappen und Relief, gelaufen mit 5-Pfennig Bayern-Marke | H12: Ja | I12: 1901 | J12: Regensburg / Wiesenfelden, 13.12.1901 | K12: Hochwürden Herrn Pfarrer Anton Windhager, Wiesenfelden b. Wörth a.d. Donau | L12: 6 | M12: 12 | N12: =MAX(L12,M12) -> 12 | O12: Im Bestand | P12: Lithografie, Wappen, Relief, Fürst Thurn und Taxis
A13: AK-2026-0012 | B13: Passau – Panorama-Gesamtansicht vom Fluss aus | C13: A. Hermann, Passau | D13: Passau | E13: Topografie / Lithografie | F13: Gut (Z2) | G13: Vorderseitig mit handschriftlichem Text, gelaufen mit 5-Pfennig Bayern-Marke | H13: Ja | I13: 1903 | J13: Passau / Wiesenfelden, 27.08.1903 | K13: Hochwürden Herrn Pfarrer Anton Windhager, Wiesenfelden b. Wörth a.d. Donau | L13: 5 | M13: 10 | N13: =MAX(L13,M13) -> 10 | O13: Im Bestand | P13: Kolorierte Lithografie, Flussansicht, Sütterlin / Handschrift
A14: AK-2026-0013 | B14: München – Karlstor mit bayerischem Wappen und Löwen | C14: Historischer Kunstverlag / Litho | D14: München | E14: Topografie / Lithografie | F14: Sehr gut (Z1-2) | G14: Prächtige Wappen-Lithografie mit Sütterlin-Text, gelaufen mit 5-Pfennig Bayern-Marke | H14: Ja | I14: 1901 | J14: München / Straubing / Wiesenfelden, 18.08.1901 | K14: Hochwürden Herrn Pfarrer Anton Windhager, Wiesenfelden b. Wörth a.d. Donau | L14: 6 | M14: 12 | N14: =MAX(L14,M14) -> 12 | O14: Im Bestand | P14: Lithografie, Bayerisches Wappen, Löwen, Karlstor
A15: AK-2026-0014 | B15: Regensburg – Gruss aus Regensburg (Dom, Bischof Ignatius, Altar) | C15: Verlag von Jakob Frankel, Regensburg (No. 100) | D15: Regensburg | E15: Topografie / Mehrbild-Lithografie | F15: Gut (Z2) | G15: Mehrbild-Lithografie mit Porträt Bischof Ignatius, gelaufen mit 5-Pfennig Bayern-Marke | H15: Ja | I15: 1900 | J15: Regensburg / Straubing / Wiesenfelden, 09.06.1900 | K15: H. Hochwürden Herrn Pfarrer Anton Windhager, Wiesenfelden b. Wörth a.d. Donau | L15: 5 | M15: 10 | N15: =MAX(L15,M15) -> 10 | O15: Im Bestand | P15: Lithografie, Bischof Ignatius, Dom Regensburg, Mehrbild
A16: AK-2026-0015 | B16: München – Gruss vom Hofbräuhaus (Junge mit Bierkrug und Dackel) | C16: Ottmar Zieher, München | D16: München | E16: Künstlerkarte / Humor | F16: Sehr gut (Z1-2) | G16: Farbige Litho mit Junge in Tracht und Dackel, gelaufen mit 5-Pfennig Bayern-Marke | H16: Ja | I16: 1902 | J16: Straubing / Wiesenfelden, 11.03.1902 | K16: Hochwürden Herrn Pfarrer Anton Windhager, Wiesenfelden b. Wörth a.d. Donau | L16: 6 | M16: 12 | N16: =MAX(L16,M16) -> 12 | O16: Im Bestand | P16: Ottmar Zieher Verlag, Hofbräuhaus, Dackel, Tracht
A17: AK-2026-0016 | B17: Regensburg – Gruss aus Regensburg (Walhalla, Brücke, Neupfarrkirche) | C17: Verlag von Jakob Frankel, Regensburg | D17: Regensburg | E17: Topografie / Mehrbild-Lithografie | F17: Gut (Z2) | G17: Farbige Lithografie mit Weinlaub-Rahmung, gelaufen mit 5-Pfennig Bayern-Marke | H17: Ja | I17: 1899 | J17: Regensburg / Straubing / Wiesenfelden, 15.07.1899 | K17: Hochwürden Hochwohlgeboren Herrn Anton Windhager, Pfarrer, Wiesenfelden b. Wörth a.d. Donau | L17: 5 | M17: 10 | N17: =MAX(L17,M17) -> 10 | O17: Im Bestand | P17: Mehrbild, Walhalla, Steinerne Brücke, Jugendstil-Ornamentik
A18: AK-2026-0017 | B18: Regensburg – Moltkeplatz im Schnee (Nachtschneekarte mit Dom) | C18: Hermann Martin, Kunstverlag, Nürnberg (No. 939) | D18: Regensburg | E18: Topografie / Nachtschneekarte | F18: Sehr gut (Z1-2) | G18: Stimmungsvolle Nachtansicht im Schnee mit Sternenhimmel, gelaufen mit 5-Pfennig Bayern-Marke | H18: Ja | I18: 1901 | J18: Regensburg / Straubing / Wiesenfelden, 29.01.1901 | K18: Hochwürden Hochwohlgeboren Herrn Anton Windhager, Pfarrer, Wiesenfelden b. Wörth a.d. Donau | L18: 8 | M18: 15 | N18: =MAX(L18,M18) -> 15 | O18: Im Bestand | P18: Nachtschneekarte, Sternenhimmel, Regensburger Dom, Moltkeplatz
A19: AK-2026-0018 | B19: München – Justizpalast und Treppenhaus | C19: Druck u. Verlag von Louis Glaser, Leipzig (No. 5268) | D19: München | E19: Topografie / Mehrbild-Lithografie | F19: Gut (Z2) | G19: Farbige Litho mit Justizpalast und Prunktreppenhaus, gelaufen mit 5-Pfennig Bayern-Marke | H19: Ja | I19: 1898 | J19: München / Straubing / Wiesenfelden, 02./03.08.1898 | K19: H. Hochwürden Herrn Anton Windhager, Pfarrer, Wiesenfelden über Straubing | L19: 5 | M19: 10 | N19: =MAX(L19,M19) -> 10 | O19: Im Bestand | P19: Justizpalast, Treppenhaus, Louis Glaser Verlag, Mehrbild
A20: AK-2026-0019 | B20: Altenthann – Ortsansicht, Gasthof Gansmeier und Schulhaus | C20: Foto-Elfner, Regensburg, St. Petersweg 19 | D20: Altenthann | E20: Topografie / Mehrbild-Ansichtskarte | F20: Sehr gut (Z1-2) | G20: Mehrbildkarte mit Gasthof Gansmeier, gelaufen mit 6-Pfennig Deutsches Reich Marke | H20: Ja | I20: 1943 | J20: Otterbach / Lupburg, 29.10.1943 | K20: Frl. Gabriele Sauerer in Lupburg, Post Lupburg | L20: 4 | M20: 8 | N20: =MAX(L20,M20) -> 8 | O20: Im Bestand | P20: Altenthann, Gasthof Gansmeier, Mehrbild, Weltkriegszeit 1943
A21: AK-2026-0020 | B21: Regensburg – Walhalla (Ansicht von unten mit den Terrassen) | C21: O. Schleich Nacht., Dresden, Doppeltonlichtdruck (No. 4491) | D21: Regensburg / Donaustauf | E21: Topografie / Echt-Lichtdruck | F21: Gut (Z2) | G21: Einfarbiger Doppelton-Lichtdruck, gelaufen mit Stempel von Regensburg | H21: Ja | I21: 1905 | J21: Regensburg / Parsberg, 03.06.1905 | K21: Herrn Joseph P. Pandarm?, Parsberg | L21: 3 | M21: 7 | N21: =MAX(L21,M21) -> 7 | O21: Im Bestand | P21: Walhalla, Donaustauf, O. Schleich Nacht. Dresden, Lichtdruck
A22: AK-2026-0021 | B22: Regensburg – Panorama mit Postillon und Briefkasten | C22: Verlag von Jakob Frankel, Regensburg | D22: Regensburg | E22: Topografie / Postkarten-Motiv-Lithografie | F22: Gut (Z2) | G22: Farblitho mit Postbote, Pferd und Regensburger Altstadt-Panorama, gelaufen | H22: Ja | I22: 1903 | J22: Nabburg / Oberviechtach / Bernhardswald / Pirkensee, 15./16.10.1903 | K22: An Herrn Joh. Gansmeier, Pirkensee | L22: 6 | M22: 12 | N22: =MAX(L22,M22) -> 12 | O22: Im Bestand | P22: Postillon, Jakob Frankel Verlag, Regensburger Dom, Litho
A23: AK-2026-0022 | B23: Regensburg – Gruss aus Regensburg (Donau-Ansicht mit Wappen) | C23: Verlag von Jakob Frankel, Regensburg (No. 254) | D23: Regensburg | E23: Topografie / Passepartout-Lithografie | F23: Gut (Z2) | G23: Passepartout-Karte mit Reliefprägung, Wappen und Farblitho, gelaufen | H23: Ja | I23: 1902 | J23: Regensburg / Nabburg / Oberviechtach, 23.10.1902 | K23: Herrn Josef Gansmeier, Pirkensee b. Burglengenfeld | L23: 6 | M23: 12 | N23: =MAX(L23,M23) -> 12 | O23: Im Bestand | P23: Passepartout, Wappen, Jakob Frankel Verlag, Donau-Ansicht
... A31: AK-2026-0030 | B31: Ingolstadt – Gruss aus Ingolstadt (Donauansicht mit Brücke) | C31: Chr. Bayerlein jr., Ingolstadt (No. 1240) | D31: Ingolstadt | E31: Topografie / Ansichtskarte | F31: Gut (Z2) | G31: S/W-Ansichtskarte mit Zierrand/Prägung, gelaufen mit Stempel Ingolstadt und Ankunftsstempel Schleiz | H31: Ja | I31: 1901 | J31: Ingolstadt / Schleiz / Plottersdorf, 04.05.1901 | K31: An Herrn Otto Raithel bei Herrn Pastor Dr. Haller, Plottersdorf b. Schleiz (Reuß) | L31: 3.5 | M31: 7 | N31: =MAX(L31,M31) -> 7 | O31: Im Bestand | P31: Ingolstadt, Donau, Bayerlein Verlag, 1901
A32: AK-2026-0031 | B32: Gößweinstein – Gruss aus Gößweinstein, Fränkische Schweiz (Mehrbild-Echtphoto) | C32: Kunstverlagsanstalt F. v. Leistner & Demartin, Muggendorf/Ofr. (12/804) | D32: Gößweinstein | E32: Topografie / Mehrbild-Echtphotokarte | F32: Sehr gut (Z1-2) | G32: S/W-Echtphotokarte mit vielen Ansichten, Wappen/Spruch und gezahntem Rand, ungelaufen | H32: Nein | J32: Unbekannt | K32: Unbekannt | L32: 4 | M32: 8 | N32: =MAX(L32,M32) -> 8 | O32: Im Bestand | P32: Gößweinstein, Fränkische Schweiz, Leistner & Demartin, Mehrbildkarte, Echtphoto
A33: AK-2026-0032 | B33: Burglengenfeld – Naabbrücke mit Burg | C33: Maria Lautenschlager, Schreibwaren, Burglengenfeld (78451) | D33: Burglengenfeld | E33: Topografie / Ansichtskarte | F33: Sehr gut (Z1-2) | G33: S/W-Ansichtskarte der Naabbrücke mit der Burg im Hintergrund, gelaufen mit 6-Pfennig Deutsches-Reich-Marke | H33: Ja | I33: 1941 | J33: Burglengenfeld / Lupburg, 26.06.1941 | K33: Familie Josef Laurer, Lupburg über Parsberg | L33: 4 | M33: 8 | N33: =MAX(L33,M33) -> 8 | O33: Im Bestand | P33: Burglengenfeld, Naabbrücke, Burg, Lautenschlager, Oberpfalz
A34: AK-2026-0033 | B34: Gasthof - Metzgerei „Zum Burgblick“ Burglengenfeld/Opf. | C34: Schwarz-Verlag GmbH, 7832 Kenzingen/Breisgau (Bestell-Nr. 5233 s) | D34: Burglengenfeld / Oberpfalz / Bayern | E34: Burglengenfeld / Gasthof Zum Burgblick / Metzgerei / Gastronomie / Heimatkarte | F34: Ungelaufen / Sehr gut (Z1-2) | G34: Ungelaufene Werbe-Ansichtskarte des Gasthofs und der Metzgerei „Zum Burgblick“ (Familie Peter Sauerer, Naabgasse 7, 8412 Burglengenfeld/Opf.) mit Innen- und Außenansichten | H34: Nein | I34: Keiner | J34: Keiner | K34: Keine | L34: 5 | M34: 10 | N34: =MAX(L34,M34) -> 10 | O34: Im Bestand | P34: Lokale Werbe-Ansichtskarte des Gasthofs Zum Burgblick in Burglengenfeld (Oberpfalz) | Q34: Sehr guter Zustand, minimale Kantenbestoßungen, unbeschrieben, rückseitig unbeschrieben
A35: AK-2026-0034 | B35: Gößweinstein – Höhenkurort Gössweinstein, Blick vom Gernerfels (Echtphoto) | C35: Kunstanstalt E. von Leistner, Muggendorf | D35: Gößweinstein | E35: Topografie / Echtphotokarte | F35: Gut bis Sehr gut (Z2+) | G35: S/W-Echtphotokarte mit Stempel Gössweinstein (500m) vom 17.07.1933, gelaufen | H35: Ja | I35: 1933 | J35: Gößweinstein / Parsberg, 17.07.1933 | K35: Herrn Josef Sauerer, Gasanstaltspächter, Parsberg (Oberpfalz) | L35: 4 | M35: 8 | N35: =MAX(L35,M35) -> 8 | O35: Im Bestand | P35: Gößweinstein, Gernerfels, Leistner, Bromsilber-Abzug, 1933
A36: AK-2026-0035 | B36: Parsberg i. Opf. – Südansicht & Östliche Ansicht (Mehrbild) | C36: Verlag A. Bermüller, Parsberg (439) | D36: Parsberg | E36: Topografie / Mehrbild-Ansichtskarte | F36: Gut (Z2) | G36: S/W-Mehrbildkarte mit Schloss Parsberg, gelaufen mit Stempel Lupburg vom 03.07.1909 | H36: Ja | I36: 1909 | J36: Lupburg / Holnstein b. Berching, 02.07.1909 | K36: Herrn Joseph Sauerer, Gand. Forst. [Gendarmerie-Station / Forstamt], Holnstein b. Berching | L36: 4 | M36: 8 | N36: =MAX(L36,M36) -> 8 | O36: Im Bestand | P36: Parsberg, Oberpfalz, Schloss Parsberg, Bermüller Verlag, 1909
A37: AK-2026-0036 | B37: Amberg Opf. – St. Georgskirche | C37: F. H. Dennerlein, Kunstverlag, Nürnberg (6) | D37: Amberg | E37: Topografie / Ansichtskarte | F37: Gut bis Sehr gut (Z2+) | G37: S/W-Ansichtskarte mit Stempel Amberg vom 18.03.1955 und Notopfer-Marke, gelaufen | H37: Ja | I37: 1955 | J37: Amberg / Lupburg, 18.03.1955 | K37: Gend. Kommissar Josef Sauerer, Lupburg, Kreis Parsberg | L37: 3 | M37: 6 | N37: =MAX(L37,M37) -> 6 | O37: Im Bestand | P37: Amberg, St. Georgskirche, Dennerlein Verlag, 1955, Notopfer Berlin
A38: AK-2026-0037 | B38: Regensburg – Seminar Obermünster, Portal | C38: Unbekannt / Verlagslos | D38: Regensburg | E38: Topografie / Ansichtskarte | F38: Gut bis Sehr gut (Z2+) | G38: S/W-Ansichtskarte mit Stempel Regensburg (Deutsches Reich 6 Pf-Marke), gelaufen | H38: Ja | I38: Unbekannt | J38: Regensburg / Lupburg b. Parsberg | K38: Herrn Jos. Sauerer, Gend. Oberkommissär a. D., Lupburg b. Parsberg | L38: 3 | M38: 6 | N38: =MAX(L38,M38) -> 6 | O38: Im Bestand | P38: Regensburg, Obermünster, Seminar, Portal, Kirche
A39: AK-2026-0038 | B39: Bad Reichenhall – Bayerisches Feuerwehr-Erholungsheim & Predigtstuhl | C39: Martin Herpich, Kunst- u. Verlagsanstalt, München | D39: Bad Reichenhall | E39: Topografie / Ansichtskarte | F39: Gut bis Sehr gut (Z2+) | G39: S/W-Ansichtskarte mit Sonderstempel „Predigtstuhl-Bahn Bad Reichenhall“ und Stempel vom 07.09.1936, gelaufen | H39: Ja | I39: 1936 | J39: Bad Reichenhall / Lupburg b. Parsberg, 07.09.1936 | K39: Frau Lina Sauerer, Lupburg b. Parsberg, Opf. | L39: 4 | M39: 8 | N39: =MAX(L39,M39) -> 8 | O39: Im Bestand | P39: Bad Reichenhall, Feuerwehr-Erholungsheim, Predigtstuhlbahn, Berchtesgadener Land, 1936
A40: AK-2026-0039 | B40: Linz a. D. – Pöstlingberg (Fliegeraufnahme / Luftbild) | C40: Österreichische Luftbild-Industrie Bad Ischl (896) | D40: Linz (Österreich) | E40: Topografie / Luftbild-Ansichtskarte | F40: Gut bis Sehr gut (Z2+) | G40: Sepia-Luftbildkarte mit Stempel vom August 1940, gelaufen | H40: Ja | I40: 1940 | J40: Linz / Lupburg b. Parsberg, 01.08.1940 | K40: Familie Jos. Sauerer, Gend. Oberkommissär a. D., Lupburg b. Parsberg u. Regensburg bey. Oberpfg. | L40: 3 | M40: 6 | N40: =MAX(L40,M40) -> 6 | O40: Im Bestand | P40: Linz, Pöstlingberg, Österreich, Luftbild, Fliegeraufnahme, 1940
A41: AK-2026-0040 | B41: Donaustauf bei Regensburg – Walhalla | C41: Unbekannt / Verlagslos | D41: Donaustauf | E41: Topografie / Ansichtskarte | F41: Gut (Z2) | G41: S/W-Ansichtskarte mit Stempel Donaustauf, gelaufen | H41: Ja | I41: Unbekannt | J41: Donaustauf / [Empfängerort unklar] | K41: Herrn Josef Sauerer, [Gendarmerie / Kumpfmühl bei Regensburg] | L41: 3 | M41: 6 | N41: =MAX(L41,M41) -> 6 | O41: Im Bestand | P41: Donaustauf, Walhalla, Regensburg, Monumentalbau, Ruhmeshalle
A42: AK-2026-0041 | B42: Donaustauf – Walhalla (Tempel deutscher Ehren) | C42: Hermann Martin, Kunstverlag, Nürnberg (1033) | D42: Donaustauf | E42: Topografie / Litho-Ansichtskarte | F42: Gut bis Sehr gut (Z2+) | G42: Kolorierte Ansichtskarte mit Stempel Fürth (Bayern) und Ankunftsstempel Velburg vom August 1904, gelaufen | H42: Ja | I42: 1904 | J42: Fürth (Bayern) / Velburg, 03.08.1904 | K42: Herrn Joseph Sauerer, kgl. Gendarm, Velburg | L42: 4 | M42: 8 | N42: =MAX(L42,M42) -> 8 | O42: Im Bestand | P42: Donaustauf, Walhalla, König Ludwig I., Koloriert, Litho, 1904, Velburg, Fürth
A43: AK-2026-0042 | B43: Parsberg – Schloßaufgang | C43: Verlag: Buchhandlung L. Bermüller, Parsberg (P 5038 42) | D43: Parsberg | E43: Topografie / Ansichtskarte | F43: Sehr gut (Z1- bis Z2+) | G43: S/W-Ansichtskarte mit Schloss Parsberg und Aufgang, ungelaufen | H43: Nein | J43: Unbekannt | K43: Unbekannt / Ohne Empfänger | L43: 2 | M43: 5 | N43: =MAX(L43,M43) -> 5 | O43: Im Bestand | P43: Parsberg, Schloßaufgang, Zwiebeltürme, Schloss, Bermüller Verlag, Oberpfalz
A44: AK-2026-0043 | B44: Regensburg – Am Wiedfang | C44: Unbekannt / Verlagslos | D44: Regensburg | E44: Topografie / Ansichtskarte | F44: Gut bis Sehr gut (Z2+) | G44: S/W-Ansichtskarte mit Stempel Regensburg vom Juli (Deutsches Reich), gelaufen | H44: Ja | I44: Unbekannt | J44: Regensburg / Velburg b. Parsberg (bzw. geändert) | K44: Herrn Joseph Sauerer, Gend. Oberkommissär a. D., Velburg b. Parsberg | L44: 3 | M44: 6 | N44: =MAX(L44,M44) -> 6 | O44: Im Bestand | P44: Regensburg, Am Wiedfang, Brunnen, Altstadt, historisch
A45: AK-2026-0044 | B45: Lupburg – Neue Pfarrkirche (Innenraum / Altarraum) | C45: Photo-Perras, Photobedarf, Parsberg (f 17) | D45: Lupburg | E45: Topografie / Ansichtskarte | F45: Sehr gut (Z1- bis Z2+) | G45: S/W-Ansichtskarte vom Kircheninneren, ungelaufen | H45: Nein | J45: Unbekannt | K45: Unbekannt / Ohne Empfänger | L45: 2 | M45: 5 | N45: =MAX(L45,M45) -> 5 | O45: Im Bestand | P45: Lupburg, Neue Pfarrkirche, Innenansicht, Altar, Kanzel, Photo-Perras, Parsberg, Oberpfalz
A46: AK-2026-0045 | B46: München – Königl. Hofbräuhaus (Gruss aus München) | C46: Verlag & Druck Kunst-Anstalt Rosenblatt, Frankfurt a. M. (4762) | D46: München | E46: Topografie / Litho-Ansichtskarte | F46: Gut bis Sehr gut (Z2+) | G46: Kolorierte Litho-Ansichtskarte mit Stempel Muenchen vom 18.12.1900 und Ankunftsstempel Wiesenfelden, gelaufen | H46: Ja | I46: 1900 | J46: Muenchen / Wiesenfelden, 18.12.1900 | K46: Wohlgeb. Herrn Andreas Windberger, Kgl. Pfarrer Wohlgeboren, Wiesenfelden b. Thierhaupten (bzw. Vilsbiburg / Opf.) | L46: 4 | M46: 8 | N46: =MAX(L46,M46) -> 8 | O46: Im Bestand | P46: München, Hofbräuhaus, Gruss aus München, Bierkrug, Litho, koloriert, 1900, Wiesenfelden, Rosenblatt Verlag
A47: AK-2026-0046 | B47: Rosenheim – Gruss aus Rosenheim (Alpenpanorama) | C47: Verlag Arno Loth, Rosenheim (4367) | D47: Rosenheim | E47: Topografie / Litho-Ansichtskarte | F47: Gut bis Sehr gut (Z2+) | G47: Kolorierte Litho-Ansichtskarte mit Stempel Rosenheim und Ankunftsstempel Wiesenfelden vom 29.08.1903, gelaufen | H47: Ja | I47: 1903 | J47: Rosenheim / Wiesenfelden, 28./29.08.1903 | K47: Hochwürdigen Herrn Pfarrer Al. Windbarger, Fräulein in Wiesenfelden (Thierhaupten / Opf.) | L47: 4 | M47: 8 | N47: =MAX(L47,M47) -> 8 | O47: Im Bestand | P47: Rosenheim, Gruss aus Rosenheim, Alpen, Panorama, Litho, koloriert, 1903, Arno Loth Verlag
...

Sheet Save
